Workbook
Name \a: #REF!
Name \b: #REF!
Name \c: #REF!
Name \d: #N/A
Name \e: #REF!
Name \f: #N/A
Name \g: #REF!
Name \h: #N/A
Name \i: #REF!
Name \l: #REF!
Name \n: #REF!
Name \o: #REF!
Name \p: #REF!
Name \q: #REF!
Name \r: #REF!
Name \s: #N/A
Name \t: #REF!
Name \v: #REF!
Name \w: #REF!
Name \x: #REF!
Name \y: #REF!
Name \z: #REF!
Name __________Less_Misc_expenditure: #REF!
Name __________Less_Misc_expenditure: #REF!
Name __________Reserves_n_surplus: #REF!
Name __________Reserves_n_surplus: #REF!
Name __________Revaluation_reserves: #REF!
Name __________Revaluation_reserves: #REF!
Name ______Current_Year_maturity: #REF!
Name ______Current_Year_maturity: #REF!
Name ______Long_term_borrowings: #REF!
Name ______Long_term_borrowings: #REF!
Name ______Short_term_borrowings: #REF!
Name ______Short_term_borrowings: #REF!
Name ______Trade_Payables: #REF!
Name ______Trade_Payables: #REF!
Name _____Deferred_tax_Assets: #REF!
Name _____Deferred_tax_Assets: #REF!
Name _____Fixed_assets_Net_block: #REF!
Name _____Fixed_assets_Net_block: #REF!
Name _____Goodwill_on_Consolidation: #REF!
Name _____Goodwill_on_Consolidation: #REF!
Name _____Long_Term_loans_and_advances: #REF!
Name _____Long_Term_loans_and_advances: #REF!
Name _____Non_current_Investments: #REF!
Name _____Non_current_Investments: #REF!
Name _____Other_non_current_assets: #REF!
Name _____Other_non_current_assets: #REF!
Name _____Share_Capital: #REF!
Name _____Share_Capital: #REF!
Name ____Minorities_interests_BS: #REF!
Name ____Minorities_interests_BS: #REF!
Name ____Share_application_money_pending_allotment: #REF!
Name ____Share_application_money_pending_allotment: #REF!
Name ____Shareholders_funds: #REF!
Name ____Shareholders_funds: #REF!
Name ___Adjusted_EPS_Rs: #REF!
Name ___Adjusted_EPS_Rs: #REF!
Name ___Adjustment_to_Profits: #REF!
Name ___Adjustment_to_Profits: #REF!

Sheet Front page
A1: Mirae Asset Capital Markets
A2: Coforge
A5: Sector Name | B5: IT Services
A7: Analyst Name | B7: Ashis Dash | C7: Rhea Baid
A8: Contact Number | B8: 022 6266 1300/+ 91 9545037868
A9: Email | B9: ashis.dash@miraeassetcm.com | C9: rhea.baid@miraeassetcm.com

Sheet Valuation
B2: CMP
B3: CMP | C3: =C21 -> 1445.9 | D3: =TODAY() -> 46216
B4: No of shares (MN) | C4: =442671546/10^6 -> 442.67155
B5: Mkt Cap (Rs mn) | C5: =C3*C4 -> 640058.79
D8: 46813 | F8: Rs. Cr | G8: FY19 | H8: FY20 | I8: FY21 | J8: FY22 | K8: FY23 | L8: FY24 | M8: FY25 | N8: FY26E | O8: FY27E | P8: FY28E | Q8: FY29E
B9: Target PE | D9: 24 | F9: USD revenue (mn) | G9: ='P&L consol'!BF5 -> 527 | H9: ='P&L consol'!BG5 -> 592.16981 | I9: ='P&L consol'!BH5 -> 627.7 | J9: ='P&L consol'!BI5 -> 866.5 | K9: ='P&L consol'!BJ5 -> 1001.7 | L9: ='P&L consol'!BK5 -> 1099.3 | M9: ='P&L consol'!BL5 -> 1448 | N9: ='P&L consol'!BM5 -> 2470 | ... Q9: ='P&L consol'!BP5 -> 3651.7096
B10: EPS | D10: =P16 -> 69.673781 | H10: =H9/G9-1 -> 0.12366188 | I10: =I9/H9-1 -> 0.06 | J10: =J9/I9-1 -> 0.38043651 | K10: =K9/J9-1 -> 0.15603001 | L10: =L9/K9-1 -> 0.097434362 | M10: =M9/L9-1 -> 0.31720186 | N10: =N9/M9-1 -> 0.7058011 | O10: =O9/N9-1 -> 0.07345844 | ... Q10: =Q9/P9-1 -> 0.16226889
B11: TP | D11: =D9*D10 -> 1672.1707
B12: Dividend | F12: Earnings and valuation metrics
B13: Calculated TP | D13: =D11 -> 1672.1707 | F13: (YE Mar) | G13: FY19 | H13: FY20 | I13: FY21 | J13: FY22 | K13: FY23 | L13: FY24 | M13: FY25 | N13: FY26 | O13: FY27E | P13: FY28E | Q13: FY29E
B14: Upside | D14: =D13/C3-1 -> 0.15649129 | F14: Revenue (INR mn) | G14: ='P&L consol'!BF12 -> 36762 | H14: ='P&L consol'!BG12 -> 41839 | I14: ='P&L consol'!BH12 -> 46628 | J14: ='P&L consol'!BI12 -> 64320 | K14: ='P&L consol'!BJ12 -> 80146 | L14: ='P&L consol'!BK12 -> 90089 | M14: ='P&L consol'!BL12 -> 120733 | N14: ='P&L consol'!BM12 -> 164027 | ... Q14: ='P&L consol'!BP12 -> 354215.83
B15: Rating | D15: BUY | F15: Adjusted PAT (INR mn) | G15: ='P&L consol'!BF66 -> 4090 | H15: ='P&L consol'!BG66 -> 4511 | I15: ='P&L consol'!BH66 -> 4735 | J15: ='P&L consol'!BI66 -> 6617 | K15: ='P&L consol'!BJ66 -> 8117 | L15: ='P&L consol'!BK66 -> 8486.3 | M15: ='P&L consol'!BL66 -> 8121 | N15: ='P&L consol'!BM66 -> 13746 | ... Q15: ='P&L consol'!BP66 -> 36183.188
F16: EPS (Rs) | G16: ='P&L consol'!BF73 -> 13.1 | H16: ='P&L consol'!BG73 -> 14.28 | I16: ='P&L consol'!BH73 -> 14.94 | J16: ='P&L consol'!BI73 -> 21.8 | K16: ='P&L consol'!BJ73 -> 26.62 | L16: ='P&L consol'!BK73 -> 26.344 | M16: ='P&L consol'!BL73 -> 24.41 | N16: ='P&L consol'!BM73 -> 40.551532 | ... Q16: ='P&L consol'!BP73 -> 81.160817
F17: PE (x) | G17: =Ratios!B72 -> 111.8855 | H17: =Ratios!C72 -> 101.2535 | I17: =Ratios!D72 -> 96.780455 | J17: =Ratios!E72 -> 66.325688 | K17: =Ratios!F72 -> 54.316304 | L17: =Ratios!G72 -> 54.885363 | M17: =Ratios!H72 -> 59.233921 | N17: =Ratios!I72 -> 35.655866 | ... Q17: =Ratios!L72 -> 17.815247
F18: EV/EBITDA | G18: =Ratios!B77 -> 99.137428 | H18: =Ratios!C77 -> 87.666498 | I18: =Ratios!D77 -> 80.412486 | J18: =Ratios!E77 -> 57.416155 | K18: =Ratios!F77 -> 45.534319 | L18: =Ratios!G77 -> 42.455616 | M18: =Ratios!H77 -> 37.19792 | N18: =Ratios!I77 -> 20.888419 | ... Q18: =Ratios!L77 -> 8.6565373
F19: P/B (x) | G19: =Ratios!B74 -> 31.309351 | H19: =Ratios!C74 -> 26.708065 | I19: =Ratios!D74 -> 25.954292 | J19: =Ratios!E74 -> 23.418784 | K19: =Ratios!F74 -> 20.764275 | L19: =Ratios!G74 -> 17.649004 | M19: =Ratios!H74 -> 10.033528 | N19: =Ratios!I74 -> 6.7108999 | ... Q19: =Ratios!L74 -> 1.9113532
F20: EV/Sales | G20: =Ratios!B76 -> 17.399344 | H20: =Ratios!C76 -> 15.080088 | I20: =Ratios!D76 -> 13.56189 | J20: =Ratios!E76 -> 9.9567753 | K20: =Ratios!F76 -> 7.9841014 | L20: =Ratios!G76 -> 7.1481178 | M20: =Ratios!H76 -> 5.3048776 | N20: =Ratios!I76 -> 3.8795124 | ... Q20: =Ratios!L76 -> 1.6991593 | AH20: 4500000
B21: #VALUE! | C21: {=_FV(B21,"Price")} -> 1445.9 | F21: ROE (%) | G21: =Ratios!B29 -> 0.19736525 | H21: =Ratios!C30 -> 0.21690628 | I21: =Ratios!D29 -> 0.19475178 | J21: =Ratios!E29 -> 0.25453916 | K21: =Ratios!F29 -> 0.27914575 | L21: =Ratios!G29 -> 0.25297879 | M21: =Ratios!H29 -> 0.16232585 | N21: =Ratios!I29 -> 0.17272316 | O21: =Ratios!J29 -> 0.13154613 | P21: =Ratios!K29 -> 0.10490866 | Q21: =Ratios!L29 -> 0.11261378 | AH21: =AH20/11 -> 409090.91
F22: ROCE (%) | G22: =Ratios!B31 -> 0 | H22: =Ratios!C31 -> 19.146614 | I22: =Ratios!D31 -> 19.142167 | J22: =Ratios!E31 -> 25.225097 | K22: =Ratios!F31 -> 25.473016 | L22: =Ratios!G31 -> 23.64621 | M22: =Ratios!H31 -> 13.848167 | N22: =Ratios!I31 -> 20.639397 | ... Q22: =Ratios!L31 -> 10.48905
F23: NWC (days) | G23: =Ratios!B41 -> 37.989959 | H23: =Ratios!C41 -> 46.324237 | I23: =Ratios!D41 -> 50.92294 | J23: =Ratios!E41 -> 36.054058 | K23: =Ratios!F41 -> 37.156099 | L23: =Ratios!G41 -> 33.346312 | M23: =Ratios!H41 -> 42.472943 | N23: =Ratios!I41 -> 39.278624 | ... Q23: =Ratios!L41 -> 39
F24: Net gearing (x) | G24: =Ratios!B54 -> 0 | H24: =Ratios!C54 -> 0 | I24: =Ratios!D54 -> 0.022342971 | J24: =Ratios!E54 -> 0.17913724 | K24: =Ratios!F54 -> 0.18238443 | L24: =Ratios!G54 -> 0.2001875 | M24: =Ratios!H54 -> 0.16779533 | N24: =Ratios!I54 -> 0.076308505 | ... Q24: =Ratios!L54 -> 0.17271299
F25: EBITDA (INR mn) | G25: ='P&L consol'!BF29 -> 6452 | H25: ='P&L consol'!BG29 -> 7197 | I25: ='P&L consol'!BH29 -> 7864 | J25: ='P&L consol'!BI29 -> 11154 | K25: ='P&L consol'!BJ29 -> 14053 | L25: ='P&L consol'!BK29 -> 15168 | M25: ='P&L consol'!BL29 -> 17218 | N25: ='P&L consol'!BM29 -> 30464 | ... Q25: ='P&L consol'!BP29 -> 69527.699
F26: EBITDA margin (%) | G26: ='P&L consol'!BF30*100 -> 17.550732 | H26: ='P&L consol'!BG30*100 -> 17.201654 | I26: ='P&L consol'!BH30*100 -> 16.865403 | J26: ='P&L consol'!BI30*100 -> 17.341418 | K26: ='P&L consol'!BJ30*100 -> 17.53425 | L26: ='P&L consol'!BK30*100 -> 16.836684 | M26: ='P&L consol'!BL30*100 -> 14.261221 | N26: ='P&L consol'!BM30*100 -> 18.572552 | ... Q26: ='P&L consol'!BP30*100 -> 19.628626
AH28: 200000
AH29: =AH28/11 -> 18181.818
B30: Sensex/Nifty | C30: 79,273/ 24,577 | D30: {=ROUND(_FV(F31,"Price"),0)&"/ "&ROUND(_FV(F30,"Price"),0)} -> 76504/ 23882 | F30: #VALUE!
B31: Bloomberg | C31: COFORGE IN | F31: #VALUE! | G31: {=_FV(F31,"Price")} -> 76503.6
B32: Equity shares (mn) | C32: =C4 -> 442.67155 | F32: #VALUE! | G32: {=_FV(F32,"Price")} -> 1445.9 | T32: Old estimates | W32: Revised Estimates | Z32: Change (%)
B33: 52-wk High/Low | C33: Rs 1,396/ 1,085 | D33: {="Rs "&ROUND(_FV(F32,"52 week high",TRUE),0)&"/ "&ROUND(_FV(F32,"52 week low",TRUE),0)} -> Rs 1994/ 1008 | F33: #VALUE! | G33: {=_FV(F33,"Price")} -> 95.555 | S33: (INR mn) | T33: FY27E | U33: FY28E | V33: FY29E | W33: =T33 -> FY27E | X33: =U33 -> FY28E | Y33: =V33 -> FY29E | Z33: =W33 -> FY27E | AA33: =X33 -> FY28E | AB33: =Y33 -> FY29E
B34: Face value | C34: Rs 1 | S34: Revenue (USD mn) | T34: 2153.7603 | U34: 2455.0157 | V34: - | W34: =O9 -> 2651.4423 | X34: =P9 -> 3141.8802 | Y34: =Q9 -> 3651.7096 | Z34: =(W34/T34-1)*100 -> 23.107589 | AA34: =(X34/U34-1)*100 -> 27.978007 | AB34: =(Y34/V34-1)*100 -> #VALUE! | AF34: 45
B35: M-Cap | C35: Rs 2,690bn/USD 28.9bn | D35: {="Rs "&ROUND(_FV(F32,"Market cap",TRUE)/1000000000,0)&"bn/USD "&ROUND((_FV(F32,"Market cap",TRUE)/1000000000)/_FV(F33,"Price"),1)&"bn"} -> Rs 656bn/USD 6.9bn | S35: Revenue | T35: 198145.94 | U35: 227088.96 | V35: - | W35: =O14 -> 247909.86 | X35: =P14 -> 300049.56 | Y35: =Q14 -> 354215.83 | Z35: =(W35/T35-1)*100 -> 25.114778 | AA35: =(X35/U35-1)*100 -> 32.128645 | AB35: =(Y35/V35-1)*100 -> #VALUE! | AF35: =AF34/12 -> 3.75
B36: 3-m Avg Turnover | C36: USD 55mn | S36: EBITDA | T36: 35276.969 | U36: 40356.148 | V36: - | W36: =O25 -> 51056.026 | X36: =P25 -> 60909.653 | Y36: =Q25 -> 69527.699 | Z36: =(W36/T36-1)*100 -> 44.72906 | AA36: =(X36/U36-1)*100 -> 50.930293 | AB36: =(Y36/V36-1)*100 -> #VALUE! | AF36: 375000
S37: EBIT | T37: 27152.986 | U37: 31272.59 | V37: - | W37: ='P&L consol'!BN39 -> 38192.786 | X37: ='P&L consol'!BO39 -> 46444.497 | Y37: ='P&L consol'!BP39 -> 53476.57 | Z37: =(W37/T37-1)*100 -> 40.657779 | AA37: =(X37/U37-1)*100 -> 48.515031 | AB37: =(Y37/V37-1)*100 -> #VALUE! | AF37: =AF36/11.5 -> 32608.696
S38: PBT | T38: 25512.265 | U38: 29922.156 | V38: - | W38: ='P&L consol'!BN51 -> 33811.756 | X38: ='P&L consol'!BO51 -> 42067.494 | Y38: ='P&L consol'!BP51 -> 49109.132 | Z38: =(W38/T38-1)*100 -> 32.531377 | AA38: =(X38/U38-1)*100 -> 40.58978 | AB38: =(Y38/V38-1)*100 -> #VALUE!
B39: (%) | C39: Apr 26 | D39: Dec 25 | E39: Sep 25 | S39: PAT | T39: 19142.594 | U39: 22490.203 | V39: - | W39: =O15 -> 24981.541 | X39: =P15 -> 31062.028 | Y39: =Q15 -> 36183.188 | Z39: =(W39/T39-1)*100 -> 30.502384 | AA39: =(X39/U39-1)*100 -> 38.113597 | AB39: =(Y39/V39-1)*100 -> #VALUE!
B40: Promoters | C40: - | D40: - | E40: - | S40: EPS (INR) | T40: 54.410801 | U40: 63.926026 | V40: - | W40: =O16 -> 56.034926 | X40: =P16 -> 69.673781 | Y40: =Q16 -> 81.160817 | Z40: =(W40/T40-1)*100 -> 2.9849317 | AA40: =(X40/U40-1)*100 -> 8.9912604 | AB40: =(Y40/V40-1)*100 -> #VALUE!
B41: -Pledged
B42: FII | C42: 23.32 | D42: 34.53 | E42: 34.09
B43: DII | C43: 44.42 | D43: 53.67 | E43: 54.87 | T43: =T36/T35*100 -> 17.803528 | U43: =U36/U35*100 -> 17.771075 | V43: =V36/V35*100 -> #VALUE! | W43: =W36/W35 -> 0.20594593 | X43: =X36/X35 -> 0.20299864 | Y43: =Y36/Y35 -> 0.19628626
B44: Others | C44: =100-C43-C42 -> 32.26 | D44: =100-D43-D42 -> 11.8 | E44: =100-E43-E42 -> 11.04 | T44: =T37/T35 -> 0.13703528 | U44: =U37/U35 -> 0.13771075 | V44: =V37/V35 -> #VALUE! | W44: =W37/W35 -> 0.15405917 | X44: =X37/X35 -> 0.15478942 | Y44: =Y37/Y35 -> 0.15097171 | Z44: =(W44-T44)*10000 -> 170.23884 | AA44: =(X44-U44)*10000 -> 170.7867 | AB44: =(Y44-V44)*10000 -> #VALUE!
...

Sheet Sheet2
A1: Ke | B1: 0.125
A2: FY29 EPS | B2: 87.71
A3: CMP | B3: 1491
A4: Normalised Growth | B4: 0.15 | D4: (FY27→28 is +29%, FY28→29 is +21%, and normalised rate is ~15%),
A6: Exit multiple on FY29 EPS (x) | B6: Implied PEG (on 15%) | C6: 12M target | D6: Upside | E6: Fair value today | F6: % Change
A7: =A9/1.125 -> 18.962963 | B7: =A7/15 -> 1.2641975 | C7: =A7*$B$2 -> 1663.2415 | D7: =C7/$B$3-1 -> 0.11552078 | E7: =C7/(1+$B$1) -> 1478.4369 | F7: =E7/$B$3-1 -> -0.0084259742
A8: 20 | B8: =A8/15 -> 1.3333333 | C8: =A8*$B$2 -> 1754.2 | D8: =C8/$B$3-1 -> 0.17652582 | E8: =C8/(1+$B$1) -> 1559.2889 | F8: =E8/$B$3-1 -> 0.04580073
A9: =A11/1.125 -> 21.333333 | B9: =A9/15 -> 1.4222222 | C9: =A9*$B$2 -> 1871.1467 | D9: =C9/$B$3-1 -> 0.25496088 | E9: =C9/(1+$B$1) -> 1663.2415 | F9: =E9/$B$3-1 -> 0.11552078 | H9: Exit PE discounted to get FY29 Multiple
A10: 22 | B10: =A10/15 -> 1.4666667 | C10: =A10*$B$2 -> 1929.62 | D10: =C10/$B$3-1 -> 0.2941784 | E10: =C10/(1+$B$1) -> 1715.2178 | F10: =E10/$B$3-1 -> 0.1503808
A11: 24 | B11: =A11/15 -> 1.6 | C11: =A11*$B$2 -> 2105.04 | D11: =C11/$B$3-1 -> 0.41183099 | E11: =C11/(1+$B$1) -> 1871.1467 | F11: =E11/$B$3-1 -> 0.25496088
A14: EPS FY29 (Normalised) | B14: =Valuation!Q16 -> 81.160817
A15: FY28 PE Exit Multiple | B15: =24 -> 24
A16: Discounted PE Exit Multiple | B16: =B15/1.125 -> 21.333333
A17: Target Price | B17: =B14*B16 -> 1731.4308

Sheet P&L consol
AP1: E | AQ1: E | AR1: E | AS1: E | AT1: E | AU1: E | AV1: E | AW1: E | AX1: E | AY1: E | AZ1: E | BA1: E | BE1: A | BF1: A | BG1: A | BH1: A | BI1: A | BJ1: A | BK1: A | BL1: A | BM1: A | BN1: E | BO1: E | BP1: E
A2: =ROWS($A$2:A2) -> 1 | B2: Income Statement (Rs. mn) | C2: Q1FY13 | D2: Q2FY13 | E2: Q3FY13 | F2: Q1FY18 | G2: Q2FY18 | H2: Q3FY18 | I2: Q4FY18 | J2: Q1FY19 | K2: Q2FY19 | L2: Q3FY19 | M2: Q4FY19 | N2: Q1FY20 | O2: Q2FY20 | P2: Q3FY20 | Q2: Q4FY20 | R2: Q1FY21 | S2: Q2FY21 | T2: Q3FY21 | U2: Q4FY21 | V2: Q1FY22 | W2: Q2FY22 | X2: Q3FY22 | Y2: Q4FY22 | Z2: Q1FY23 | AA2: Q2FY23 | AB2: Q3FY23 | AC2: Q4FY23 | AD2: Q1FY24 | AE2: Q2FY24 | AF2: Q3FY24 | AG2: Q4FY24 | AH2: Q1FY25 | AI2: Q2FY25 | AJ2: Q3FY25 | AK2: Q4FY25 | AL2: Q1FY26 | AM2: Q2FY26 | AN2: Q3FY26 | AO2: Q4FY26 | AP2: Q1FY27 | AQ2: Q2FY27 | AR2: Q3FY27 | AS2: Q4FY27 | AT2: Q1FY28 | AU2: Q2FY28 | AV2: Q3FY28 | AW2: Q4FY28 | AX2: Q1FY29 | AY2: Q2FY29 | AZ2: Q3FY29 | BA2: Q4FY29 | BE2: FY18 | BF2: FY19 | BG2: FY20 | BH2: FY21 | BI2: FY22 | BJ2: FY23 | BK2: FY24 | BL2: FY25 | BM2: FY26 | BN2: FY27 | BO2: FY28 | BP2: FY29
A3: =ROWS($A$2:A3) -> 2 | J3: -2.5355659 | K3: =K5-J5 -> 5.1554841 | X3: =X5+W5+V5+U5 -> 806.2 | AB3: =AB5+AA5+Z5+Y5 -> 969.7 | AF3: =AF5+AE5+AD5+AC5 -> 1096.3 | AJ3: =AJ5+AI5+AH5+AG5 -> 1322.9 | AK3: =AK5+AJ5+AI5+AH5 -> 1445.5 | AL3: =AL5+AK5+AJ5+AI5 -> 1601.5 | AM3: =AM5+AL5+AK5+AJ5 -> 1698.5 | AN3: =AN5+AM5+AL5+AK5 -> 1788.9 | AO3: =AO5+AN5+AM5+AL5 -> 1874.5 | AS3: =AS5*4 -> 2861.5916 | AW3: =AW5*4 -> 3276.4191 | BA3: =BA5*4 -> 3837.2286
A4: =ROWS($A$2:A4) -> 3 | B4: USD/INR | F4: 64.41 | G4: ='Operating Metrics'!#REF! -> #REF! | H4: ='Operating Metrics'!#REF! -> #REF! | I4: ='Operating Metrics'!#REF! -> #REF! | J4: 67.52 | K4: ='Operating Metrics'!C270 -> 70.51 | L4: ='Operating Metrics'!D270 -> 71.66 | M4: ='Operating Metrics'!E270 -> 69.28 | N4: ='Operating Metrics'!F270 -> 68.5 | O4: ='Operating Metrics'!G270 -> 70.66 | P4: ='Operating Metrics'!H270 -> 70.97 | Q4: ='Operating Metrics'!I270 -> 71.66 | R4: =R12/R5 -> 75.553967 | S4: =S12/S5 -> 74.48031 | T4: =T12/T5 -> 74.042289 | U4: =U12/U5 -> 73.300407 | V4: =V12/V5 -> 73.189785 | W4: =W12/W5 -> 73.75 | X4: =X12/X5 -> 74.824007 | Y4: 75.3 | Z4: =Z12/Z5 -> 76.640134 | AA4: =AA12/AA5 -> 79.360065 | AB4: =AB12/AB5 -> 81.676599 | AC4: =AC12/AC5 -> 82.072617 | AD4: =AD12/AD5 -> 81.714496 | AE4: =AE12/AE5 -> 81.848256 | AF4: =AF12/AF5 -> 82.386525 | AG4: =AG12/AG5 -> 82.53471 | ... AO4: =AO12/AO5 -> 90.991617 | AP4: 93.5 | AQ4: 93.5 | AR4: 93.5 | AS4: 93.5 | AT4: 95.5 | AU4: 95.5 | AV4: 95.5 | AW4: 95.5 | AX4: 97 | AY4: 97 | AZ4: 97 | BA4: 97 | BE4: 64.6325 | BF4: =AVERAGE(J4:M4) -> 69.7425 | BG4: =AVERAGE(N4:Q4) -> 70.4475 | BH4: =AVERAGE(R4:U4) -> 74.344243 | BI4: =AVERAGE(V4:Y4) -> 74.265948 | BJ4: =AVERAGE(Z4:AC4) -> 79.937354 | BK4: =AVERAGE(AD4:AG4) -> 82.120997 | BL4: =AVERAGE(AH4:AK4) -> 83.354593 | BM4: =AVERAGE(AL4:AO4) -> 87.152953 | BN4: =AVERAGE(AP4:AS4) -> 93.5 | BO4: =AVERAGE(AT4:AW4) -> 95.5 | BP4: =AVERAGE(AX4:BA4) -> 97
A5: =ROWS($A$2:A5) -> 4 | B5: Revenues ($ mn) | F5: 110.06055 | G5: =G12/G4 -> #REF! | H5: =H12/H4 -> #REF! | I5: =I12/I4 -> #REF! | J5: 118.55746 | K5: =K12/K4 -> 123.71295 | L5: =L12/L4 -> 129.06782 | M5: =M12/M4 -> 134.51212 | N5: =N12/N4 -> 140.10219 | O5: =O12/O4 -> 146.97141 | P5: =P12/P4 -> 151.24701 | Q5: =Q12/Q4 -> 154.80045 | R5: 139.9 | S5: 154.9 | T5: 160.8 | U5: 172.1 | V5: 199.7 | W5: 212.8 | X5: 221.6 | Y5: 232.4 | Z5: 238.7 | AA5: 246.9 | AB5: 251.7 | AC5: 264.4 | AD5: 271.8 | AE5: 278.1 | AF5: 282 | AG5: 280.9 | AH5: 286.4 | AI5: 365.1 | AJ5: 390.5 | AK5: 403.5 | AL5: 442.4 | AM5: 462.1 | AN5: 480.9 | AO5: 489.1 | AP5: ='Revenue and Cost model'!AH56 -> 587.79848 | AQ5: ='Revenue and Cost model'!AI56 -> 661.15922 | AR5: ='Revenue and Cost model'!AJ56 -> 687.08675 | AS5: ='Revenue and Cost model'!AK56 -> 715.39789 | AT5: ='Revenue and Cost model'!AL56 -> 751.81101 | AU5: ='Revenue and Cost model'!AM56 -> 773.84735 | AV5: ='Revenue and Cost model'!AN56 -> 797.11708 | AW5: ='Revenue and Cost model'!AO56 -> 819.10477 | ... BA5: ='Revenue and Cost model'!AS56 -> 959.30714 | BE5: 455 | BF5: 527 | BG5: =BH5/(1+6%) -> 592.16981 | BH5: =SUM(R5:U5) -> 627.7 | BI5: =SUM(V5:Y5) -> 866.5 | BJ5: =SUM(Z5:AC5) -> 1001.7 | BK5: 1099.3 | BL5: 1448 | BM5: =1870+600 -> 2470 | BN5: =SUM(AP5:AS5) -> 2651.4423 | BO5: =SUM(AT5:AW5) -> 3141.8802 | BP5: =SUM(AX5:BA5) -> 3651.7096
A6: =ROWS($A$2:A6) -> 5 | B6: revenue growth Qoq (%) | F6: -0.041422419 | G6: =G5/F5-1 -> #REF! | H6: =H5/G5-1 -> #REF! | I6: =I5/H5-1 -> #REF! | J6: -0.020938992 | K6: =K5/J5-1 -> 0.043485107 | L6: =L5/K5-1 -> 0.043284651 | M6: =M5/L5-1 -> 0.042181734 | N6: =N5/M5-1 -> 0.041558076 | O6: =O5/N5-1 -> 0.049030087 | P6: =P5/O5-1 -> 0.029091327 | Q6: =Q5/P5-1 -> 0.023494288 | R6: =R5/Q5-1 -> -0.096255837 | ... BA6: =BA5/AZ5-1 -> 0.033609452 | BE6: 0.10705596 | BF6: =BF5/BE5-1 -> 0.15824176 | BG6: =BG5/BF5-1 -> 0.12366188 | BH6: 0.06 | BI6: =BI5/BH5-1 -> 0.38043651 | BJ6: =BJ5/BI5-1 -> 0.15603001 | BK6: =BK5/BJ5-1 -> 0.097434362 | BL6: =BL5/BK5-1 -> 0.31720186 | BM6: =BM5/BL5-1 -> 0.7058011 | BN6: =BN5/BM5-1 -> 0.07345844 | BO6: =BO5/BN5-1 -> 0.18497021 | BP6: =BP5/BO5-1 -> 0.16226889
A7: =ROWS($A$2:A7) -> 6 | F7: 0.10076959 | J7: 0.077202184 | K7: =K5/G5-1 -> #REF! | L7: =L5/H5-1 -> #REF! | M7: =M5/I5-1 -> #REF! | N7: =N5/J5-1 -> 0.1817239 | O7: =O5/K5-1 -> 0.18800347 | P7: =P5/L5-1 -> 0.17184133 | Q7: =Q5/M5-1 -> 0.15082894 | R7: =R5/N5-1 -> -0.0014431593 | ... BA7: =BA5/AW5-1 -> 0.17116537 | BE7: 0.10705596 | BF7: =BF5/BE5-1 -> 0.15824176 | BG7: =BG5/BF5-1 -> 0.12366188 | BH7: 0.06 | BJ7: 0.224
A8: =ROWS($A$2:A8) -> 7 | B8: CC growth (%) | BK8: 0.133 | BL8: 0.133
A9: =ROWS($A$2:A9) -> 8 | B9: Gross revenue
A10: =ROWS($A$2:A10) -> 9 | B10: Adjustment from Hedging Reserve | I10: 261 | AJ10: -46 | AK10: -123 | AM10: -307 | AN10: -434 | AO10: -743 | BL10: -227 | BM10: -1639
A11: =ROWS($A$2:A11) -> 10
A12: =ROWS($A$2:A12) -> 11 | B12: Revenues in INR | F12: 7089 | G12: 7372 | H12: 7565 | I12: 7888 | J12: 8005 | K12: 8723 | L12: 9249 | M12: 9319 | N12: 9597 | O12: 10385 | P12: 10734 | Q12: 11093 | R12: 10570 | S12: 11537 | T12: 11906 | U12: 12615 | V12: 14616 | W12: 15694 | X12: 16581 | Y12: 17429 | Z12: 18294 | AA12: 19594 | AB12: 20558 | AC12: 21700 | AD12: 22210 | AE12: 22762 | AF12: 23233 | AG12: 23184 | AH12: 23571 | AI12: 30256 | AJ12: 32581 | AK12: 34222 | AL12: 36886 | AM12: 39857 | AN12: 42315 | AO12: 44504 | AP12: =AP5*AP4 -> 54959.158 | AQ12: =AQ5*AQ4 -> 61818.387 | AR12: =AR5*AR4 -> 64242.612 | AS12: =AS5*AS4 -> 66889.703 | AT12: =AT5*AT4 -> 71797.951 | AU12: =AU5*AU4 -> 73902.422 | AV12: =AV5*AV4 -> 76124.681 | AW12: =AW5*AW4 -> 78224.506 | ... BA12: =BA5*BA4 -> 93052.793 | BE12: 29914 | BF12: 36762 | BG12: 41839 | BH12: 46628 | BI12: =SUM(V12:Y12) -> 64320 | BJ12: =SUM(Z12:AC12) -> 80146 | BK12: 90089 | BL12: 120733 | BM12: 164027 | BN12: =SUM(AP12:AS12) -> 247909.86 | BO12: =SUM(AT12:AW12) -> 300049.56 | BP12: =SUM(AX12:BA12) -> 354215.83
A13: =ROWS($A$2:A13) -> 12 | BE13: 0.067556476 | BF13: =BF12/BE12-1 -> 0.22892291 | BG13: =BG12/BF12-1 -> 0.13810456 | BH13: =BH12/BG12-1 -> 0.11446258 | BI13: =BI12/BH12-1 -> 0.37942867 | BJ13: =BJ12/BI12-1 -> 0.246051 | BK13: =BK12/BJ12-1 -> 0.12406109 | BL13: =BL12/BK12-1 -> 0.34015252 | BM13: =BM12/BL12-1 -> 0.35859293 | ... BP13: =BP12/BO12-1 -> 0.18052442
A14: =ROWS($A$2:A14) -> 13 | B14: EXPENSES
A15: =ROWS($A$2:A15) -> 14 | B15: Direct expenses | F15: 4577 | G15: 4791 | H15: 4811 | I15: 5000 | J15: 5301 | K15: 5720 | L15: 6032 | M15: 6110 | N15: 6348 | O15: 6796 | P15: 7069 | Q15: 7289 | R15: 7241 | S15: 7776 | T15: 8096 | U15: 8580 | V15: 10250 | W15: 10656 | X15: 11210 | Y15: 11620 | Z15: 12739 | AA15: 13316 | AB15: 13698 | AC15: 14306 | AD15: 15401 | AE15: 15374 | AF15: =AF12-AF20-4170 -> 15555 | AG15: =AG12-(AG12*34.7%) -> 15139.152 | AH15: 15975 | AI15: 20827 | AJ15: =AJ12-(AJ12*33.4%) -> 21698.946 | AK15: 22483 | AL15: 24455 | AM15: 26299 | AN15: 28112 | AO15: 29204 | AP15: ='Revenue and Cost model'!AH154 -> 37068.319 | AQ15: ='Revenue and Cost model'!AI154 -> 39431.276 | AR15: ='Revenue and Cost model'!AJ154 -> 41821.905 | AS15: ='Revenue and Cost model'!AK154 -> 43523.216 | AT15: ='Revenue and Cost model'!AL154 -> 45645.917 | AU15: ='Revenue and Cost model'!AM154 -> 47723.984 | AV15: ='Revenue and Cost model'!AN154 -> 50388.066 | AW15: ='Revenue and Cost model'!AO154 -> 51274.653 | ... BA15: ='Revenue and Cost model'!AS154 -> 62796.572 | BE15: 19179 | BF15: 23908 | BG15: 27528 | BH15: 31693 | BI15: 43737 | BJ15: =SUM(Z15:AC15) -> 54059 | BK15: =BK12-(BK12*33.2%) -> 60179.452 | BL15: 79999 | BM15: 108527 | BN15: =SUM(AP15:AS15) -> 161844.72 | BO15: =SUM(AT15:AW15) -> 195032.62 | BP15: =SUM(AX15:BA15) -> 233983.09
A16: Tax
A17: Minority Interest
A18: =ROWS($A$2:A18) -> 17 | B18: - employee cost % | F18: 0.64564819 | G18: =G15/G12 -> 0.64989148 | I18: =I15/I12 -> 0.63387424 | J18: 0.66221112 | K18: =K15/K12 -> 0.6557377 | L18: =L15/L12 -> 0.65217861 | M18: =M15/M12 -> 0.65564975 | N18: =N15/N12 -> 0.66145671 | O18: =O15/O12 -> 0.65440539 | P18: =P15/P12 -> 0.65856158 | Q18: =Q15/Q12 -> 0.65708104 | R18: =R15/R12 -> 0.68505203 | ... BA18: =BA15/BA12 -> 0.67484886 | BE18: 0.64113793 | BF18: =BF15/BF12 -> 0.65034547 | BG18: =BG15/BG12 -> 0.65795072 | BH18: =BH15/BH12 -> 0.67969889 | BI18: =BI15/BI12 -> 0.67999067 | BJ18: =BJ15/BJ12 -> 0.67450653 | BK18: =BK15/BK12 -> 0.668 | BL18: =BL15/BL12 -> 0.66261089 | BM18: =BM15/BM12 -> 0.66164107 | ... BP18: =BP15/BP12 -> 0.66056643
A19: =ROWS($A$2:A19) -> 18
A20: =ROWS($A$2:A20) -> 19 | B20: Selling / G&A | F20: 1404 | G20: 1391 | H20: 1458 | I20: 1470 | J20: 1417 | K20: 1450 | L20: 1540 | M20: 1624 | N20: 1843 | O20: 1691 | P20: 1725 | Q20: 1816 | R20: 1523 | S20: 1589 | T20: 1665 | U20: 1767 | V20: 2007 | W20: 2115 | X20: 2145 | Y20: 2260 | Z20: 2543 | AA20: 2682 | AB20: 3063 | AC20: 3150 | AD20: 3264 | AE20: 3392 | AF20: =3508 -> 3508 | AG20: =AG27-AG15-AG22 -> 3590.848 | AH20: =3361-AH22 -> 3162 | AI20: =4503-AI22 -> 4283 | AJ20: =6276-AJ22 -> 5581 | AK20: =5868-AK22 -> 5252 | AL20: =6118-AL22 -> 5525 | AM20: =6276-AM22 -> 5715 | AN20: =6468-AN22 -> 6024 | AO20: =6132-AO22 -> 5751 | AP20: ='Revenue and Cost model'!AH165 -> 6595.0989 | AQ20: ='Revenue and Cost model'!AI165 -> 8654.5742 | AR20: ='Revenue and Cost model'!AJ165 -> 8993.9656 | AS20: ='Revenue and Cost model'!AK165 -> 9030.1099 | AT20: ='Revenue and Cost model'!AL165 -> 10051.713 | AU20: ='Revenue and Cost model'!AM165 -> 10346.339 | AV20: ='Revenue and Cost model'!AN165 -> 10657.455 | AW20: ='Revenue and Cost model'!AO165 -> 10951.431 | ... BA20: ='Revenue and Cost model'!AS165 -> 12096.863 | BE20: 5723 | BF20: 6402 | BG20: 7097 | BH20: 6544 | BI20: =SUM(V20:Y20) -> 8527 | BJ20: =SUM(Z20:AC20) -> 11438 | BK20: =BK27-BK15-BK22 -> 13695.548 | BL20: =23516-BL22 -> 21774 | BM20: =25036-BM22 -> 23057 | BN20: =SUM(AP20:AS20) -> 33273.749 | BO20: =SUM(AT20:AW20) -> 42006.938 | BP20: =SUM(AX20:BA20) -> 48225.534
A21: =ROWS($A$2:A21) -> 20 | B21: - as % of revenues % | F21: 0.19805332 | G21: =G20/G12 -> 0.18868692 | H21: =H20/H12 -> 0.19272968 | I21: =I20/I12 -> 0.18635903 | J21: 0.17701437 | K21: =K20/K12 -> 0.16622722 | L21: =L20/L12 -> 0.16650449 | M21: =M20/M12 -> 0.17426763 | N21: =N20/N12 -> 0.19203918 | O21: =O20/O12 -> 0.16283101 | P21: =P20/P12 -> 0.1607043 | Q21: =Q20/Q12 -> 0.16370684 | R21: =R20/R12 -> 0.14408704 | ... BA21: =BA20/BA12 -> 0.13 | BE21: 0.1913151 | BF21: =BF20/BF12 -> 0.17414722 | BG21: =BG20/BG12 -> 0.16962643 | BH21: =BH20/BH12 -> 0.14034486 | BI21: =BI20/BI12 -> 0.13257152 | BJ21: =BJ20/BJ12 -> 0.14271455 | BK21: =BK20/BK12 -> 0.15202242 | BL21: =BL20/BL12 -> 0.18034837 | BM21: =BM20/BM12 -> 0.14056832 | ... BP21: =BP20/BP12 -> 0.13614731
A22: =ROWS($A$2:A22) -> 21 | B22: Cost of ESOPS | L22: =L23*L12 -> 0 | M22: =M23*M12 -> 0 | N22: =N23*N12 -> 0 | O22: =O23*O12 -> 0 | P22: 0 | Q22: 17 | R22: 120 | S22: =0+124 -> 124 | T22: 136 | U22: =46+100 -> 146 | V22: =124+130 -> 254 | W22: =135+51 -> 186 | X22: =158+48 -> 206 | Y22: =210+46 -> 256 | Z22: =90+4 -> 94 | AA22: =147+5 -> 152 | AB22: 182 | AC22: 168 | AD22: =216+13 -> 229 | AE22: =519+4 -> 523 | AF22: =4170-4012 -> 158 | AG22: =4473-4251 -> 222 | AH22: 199 | AI22: 220 | AJ22: 695 | AK22: 616 | AL22: 593 | AM22: 561 | AN22: 444 | AO22: 381 | AP22: =AP23*AP12 -> 384.7141 | AQ22: =AQ23*AQ12 -> 432.72871 | AR22: =AR23*AR12 -> 449.69828 | AS22: =AS23*AS12 -> 468.22792 | AT22: =AT23*AT12 -> 502.58566 | AU22: =AU23*AU12 -> 517.31695 | AV22: =AV23*AV12 -> 532.87276 | AW22: =AW23*AW12 -> 547.57154 | ... BA22: =BA23*BA12 -> 651.36955 | BG22: 17 | BH22: =46+481 -> 527 | BI22: =SUM(V22:Y22) -> 902 | BJ22: =SUM(Z22:AC22) -> 596 | BK22: 1046 | BL22: 1742 | BM22: 1979 | BN22: =SUM(AP22:AS22) -> 1735.369 | BO22: =SUM(AT22:AW22) -> 2100.3469 | BP22: =SUM(AX22:BA22) -> 2479.5108
A23: =ROWS($A$2:A23) -> 22 | B23: - as % of revenues % | Q23: =Q22/Q12 -> 0.001532498 | R23: =R22/R12 -> 0.011352886 | S23: =S22/S12 -> 0.010748028 | T23: =T22/T12 -> 0.011422812 | U23: =U22/U12 -> 0.011573524 | V23: =V22/V12 -> 0.017378216 | W23: =W22/W12 -> 0.011851663 | X23: =X22/X12 -> 0.012423859 | ... AF23: =AF22/AF12 -> 0.0068006715 | AG23: 0.0065 | AH23: =AH22/AH12 -> 0.0084425777 | AI23: =AI22/AI12 -> 0.007271285 | AJ23: =AJ22/AJ12 -> 0.021331451 | AK23: =AK22/AK12 -> 0.018000117 | AL23: =AL22/AL12 -> 0.01607656 | AM23: =AM22/AM12 -> 0.014075319 | AN23: =AN22/AN12 -> 0.010492733 | AO23: =AO22/AO12 -> 0.0085610282 | AP23: 0.007 | AQ23: 0.007 | AR23: 0.007 | AS23: 0.007 | AT23: 0.007 | AU23: 0.007 | AV23: 0.007 | AW23: 0.007 | AX23: 0.007 | AY23: 0.007 | AZ23: 0.007 | BA23: 0.007 | BG23: =BG22/BG12 -> 0.00040631946 | BH23: =BH22/BH12 -> 0.011302222 | BI23: =BI22/BI12 -> 0.014023632 | BJ23: =BJ22/BJ12 -> 0.0074364285 | BK23: =BK22/BK12 -> 0.01161074 | BL23: =BL22/BL12 -> 0.014428532 | BM23: =BM22/BM12 -> 0.012065087 | BN23: =BN22/BN12 -> 0.007 | ... BP23: =BP22/BP12 -> 0.007
A24: =ROWS($A$2:A24) -> 23 | B24: Cost of ESOPS | Z24: =Z21+Z23 -> 0.14414562
A25: =ROWS($A$2:A25) -> 24 | B25: Acquisition related expenses | AI25: 290 | AK25: 422 | AL25: 43
A26: =ROWS($A$2:A26) -> 25 | B26: One time bonus | AL26: 458
A27: =ROWS($A$2:A27) -> 26 | B27: Total expenses | F27: 5981 | G27: =G15+G20+G22 -> 6182 | H27: =H15+H20+H22 -> 6269 | I27: =I15+I20+I22 -> 6470 | J27: 6718 | K27: =K15+K20+K22 -> 7170 | L27: =L15+L20+L22 -> 7572 | M27: =M15+M20+M22 -> 7734 | N27: =N15+N20+N22 -> 8191 | O27: =O15+O20+O22 -> 8487 | P27: =P15+P20+P22 -> 8794 | Q27: =Q15+Q20+Q22 -> 9122 | R27: =R15+R20+R22 -> 8884 | ... AF27: =AF15+AF20+AF22 -> 19221 | AG27: =AG12-AG29 -> 18952 | AH27: =AH15+AH20+AH22 -> 19336 | AI27: =AI15+AI20+AI22+AI25+AI26 -> 25620 | AJ27: =AJ12-AJ29 -> 27524 | AK27: =AK15+AK20+AK22+AK25 -> 28773 | AL27: =AL15+AL20+AL22+AL25+AL26 -> 31074 | AM27: =AM15+AM20+AM22+AM25+AM26 -> 32575 | AN27: =AN15+AN20+AN22+AN25+AN26 -> 34580 | AO27: =AO15+AO20+AO22+AO25+AO26 -> 35336 | AP27: =AP15+AP20+AP22 -> 44048.132 | AQ27: =AQ15+AQ20+AQ22 -> 48518.579 | AR27: =AR15+AR20+AR22 -> 51265.569 | AS27: =AS15+AS20+AS22 -> 53021.554 | AT27: =AT15+AT20+AT22 -> 56200.216 | AU27: =AU15+AU20+AU22 -> 58587.64 | AV27: =AV15+AV20+AV22 -> 61578.395 | AW27: =AW15+AW20+AW22 -> 62773.656 | ... BA27: =BA15+BA20+BA22 -> 75544.804 | BE27: 24902 | BF27: =BF15+BF20+BF22 -> 30310 | BG27: =BG15+BG20+BG22 -> 34642 | BH27: =BH15+BH20+BH22 -> 38764 | BI27: =BI15+BI20+BI22 -> 53166 | BJ27: =BJ15+BJ20+BJ22 -> 66093 | BK27: =BK12-BK29 -> 74921 | BL27: =BL15+BL20+BL22+BL25+BL26 -> 103515 | BM27: =BM15+BM20+BM22+BM25+BM26 -> 133563 | BN27: =BN15+BN20+BN22 -> 196853.83 | BO27: =BO15+BO20+BO22 -> 239139.91 | BP27: =BP15+BP20+BP22 -> 284688.13
A28: =ROWS($A$2:A28) -> 27
A29: =ROWS($A$2:A29) -> 28 | B29: EBITDA | F29: 1108 | G29: =G12-G27 -> 1190 | H29: =H12-H27 -> 1296 | I29: =I12-I27 -> 1418 | J29: 1287 | K29: =K12-K27 -> 1553 | L29: =L12-L27 -> 1677 | M29: =M12-M27 -> 1585 | N29: =N12-N27 -> 1406 | O29: =O12-O27 -> 1898 | P29: =P12-P27 -> 1940 | Q29: =Q12-Q27 -> 1971 | R29: =R12-R27 -> 1686 | ... AF29: =AF12-AF27 -> 4012 | AG29: 4232 | AH29: =AH12-AH27 -> 4235 | AI29: =AI12-AI27 -> 4636 | AJ29: 5057 | AK29: =AK12-AK27 -> 5449 | AL29: =AL12-AL27 -> 5812 | AM29: =AM12-AM27 -> 7282 | AN29: =AN12-AN27 -> 7735 | AO29: =AO12-AO27 -> 9168 | AP29: =AP12-AP27 -> 10911.025 | AQ29: =AQ12-AQ27 -> 13299.808 | AR29: =AR12-AR27 -> 12977.043 | ... BA29: =BA12-BA27 -> 17507.989 | BE29: 5012 | BF29: =BF12-BF27 -> 6452 | BG29: =BG12-BG27 -> 7197 | BH29: =BH12-BH27 -> 7864 | BI29: =BI12-BI27 -> 11154 | BJ29: =BJ12-BJ27 -> 14053 | BK29: 15168 | BL29: =BL12-BL27 -> 17218 | BM29: =BM12-BM27 -> 30464 | BN29: =BN12-BN27 -> 51056.026 | BO29: =BO12-BO27 -> 60909.653 | BP29: =BP12-BP27 -> 69527.699
A30: =ROWS($A$2:A30) -> 29 | B30: % of revenue | F30: 0.15629849 | G30: =G29/G12 -> 0.1614216 | H30: =H29/H12 -> 0.17131527 | I30: =I29/I12 -> 0.17976673 | J30: 0.16077452 | K30: =K29/K12 -> 0.17803508 | L30: =L29/L12 -> 0.1813169 | M30: =M29/M12 -> 0.17008263 | N30: =N29/N12 -> 0.14650412 | O30: =O29/O12 -> 0.1827636 | P30: =P29/P12 -> 0.18073412 | Q30: =Q29/Q12 -> 0.17767962 | R30: =R29/R12 -> 0.15950804 | ... BA30: =BA29/BA12 -> 0.18815114 | BE30: 0.16754697 | BF30: =BF29/BF12 -> 0.17550732 | BG30: =BG29/BG12 -> 0.17201654 | BH30: =BH29/BH12 -> 0.16865403 | BI30: =BI29/BI12 -> 0.17341418 | BJ30: =BJ29/BJ12 -> 0.1753425 | BK30: =BK29/BK12 -> 0.16836684 | BL30: =BL29/BL12 -> 0.14261221 | BM30: =BM29/BM12 -> 0.18572552 | ... BP30: =BP29/BP12 -> 0.19628626
A31: =ROWS($A$2:A31) -> 30 | B31: Adjusted EBITDA margin (%) | J31: 0.16077452 | K31: =K30+K23 -> 0.17803508 | L31: =L30+L23 -> 0.1813169 | M31: =M30+M23 -> 0.17008263 | N31: =N30+N23 -> 0.14650412 | O31: =O30+O23 -> 0.1827636 | P31: =P30+P23 -> 0.18073412 | Q31: =Q30+Q23 -> 0.17921212 | R31: =R30+R23 -> 0.17086093 | ... BA31: =BA30+BA23 -> 0.19515114 | BE31: 0.16754697 | BF31: =BF30+BF23 -> 0.17550732 | BG31: =BG30+BG23 -> 0.17242286 | BH31: =BH30+BH23 -> 0.17995625 | BI31: =BI30+BI23 -> 0.18743781 | BJ31: =BJ30+BJ23 -> 0.18277893 | BK31: =BK30+BK23 -> 0.17997758 | BL31: =BL30+BL23 -> 0.15704074 | BM31: =BM30+BM23 -> 0.19779061 | ... BP31: =BP30+BP23 -> 0.20328626
A32: =ROWS($A$2:A32) -> 31 | B32: Growth (%) | Z32: =Z31-Y31 -> -0.038981995 | BE32: 0.034468524 | BF32: =BF29/BE29-1 -> 0.28731045 | BG32: =BG29/BF29-1 -> 0.11546807 | BH32: =BH29/BG29-1 -> 0.092677505 | BI32: =BI29/BH29-1 -> 0.41836216 | BJ32: =BJ29/BI29-1 -> 0.25990676 | BK32: =BK29/BJ29-1 -> 0.079342489 | BL32: =BL29/BK29-1 -> 0.13515295 | BM32: =BM29/BL29-1 -> 0.76931119 | ... BP32: =BP29/BO29-1 -> 0.14148901
A33: =ROWS($A$2:A33) -> 32 | AM33: =1251+468 -> 1719
A34: =ROWS($A$2:A34) -> 33 | B34: Depreciation | F34: 316 | G34: 341 | H34: 311 | I34: 305 | J34: 307 | K34: 314 | L34: 309 | M34: 298 | N34: 401 | O34: 447 | P34: 449 | Q34: 433 | R34: 465 | S34: 460 | T34: 462 | U34: 449 | V34: 524 | W34: 598 | X34: 566 | Y34: 584 | Z34: 630 | AA34: 614 | AB34: 624 | AC34: 717 | AD34: 757 | AE34: 772 | AF34: 811 | AG34: 792 | AH34: =549+168 -> 717 | AI34: =738+402 -> 1140 | AJ34: 1165 | AK34: =845+409 -> 1254 | AL34: =1104+488 -> 1592 | AM34: =1251+468 -> 1719 | AN34: =1229+479 -> 1708 | AO34: =1308+492 -> 1800 | AP34: =AP12*AP37 -> 3022.7537 | AQ34: =AQ12*AQ37 -> 3152.7377 | AR34: =AR12*AR37 -> 3276.3732 | AS34: =AS12*AS37 -> 3411.3749 | AT34: =AT12*AT37 -> 3661.6955 | AU34: =AU12*AU37 -> 3769.0235 | AV34: =AV12*AV37 -> 3044.9872 | AW34: =AW12*AW37 -> 3989.4498 | ... BA34: =BA12*BA37 -> 3722.1117 | BE34: 1274 | BF34: 1248 | BG34: 1730 | BH34: 1836 | BI34: 2272 | BJ34: =SUM(Z34:AC34) -> 2585 | BK34: 2972 | BL34: =2907+1369 -> 4276 | BM34: =4892+1927 -> 6819 | BN34: =SUM(AP34:AS34) -> 12863.239 | BO34: =SUM(AT34:AW34) -> 14465.156 | BP34: =SUM(AX34:BA34) -> 16051.129
A35: =ROWS($A$2:A35) -> 34 | B35: Amortisation of intangible assets | Z35: =$BJ$35/4 -> 0 | AA35: =$BJ$35/4 -> 0 | AB35: =$BJ$35/4 -> 0 | AC35: =$BJ$35/4 -> 0 | AD35: =$BK$35/4 -> 0 | AE35: =$BK$35/4 -> 0 | AF35: =$BK$35/4 -> 0 | AG35: =$BK$35/4 -> 0 | AH35: =$BK$35/4 -> 0 | AI35: =$BK$35/4 -> 0 | AJ35: =$BK$35/4 -> 0 | AK35: =$BK$35/4 -> 0 | ... BA35: =$BK$35/4 -> 0
A36: =ROWS($A$2:A36) -> 35 | B36: Growth (%) | F36: 0.012820513 | G36: =G34/F34-1 -> 0.079113924 | H36: =H34/G34-1 -> -0.08797654 | I36: =I34/H34-1 -> -0.019292605 | J36: 0.006557377 | K36: =K34/J34-1 -> 0.022801303 | L36: =L34/K34-1 -> -0.015923567 | M36: =M34/L34-1 -> -0.035598706 | N36: =N34/M34-1 -> 0.34563758 | O36: =O34/N34-1 -> 0.11471322 | P36: =P34/O34-1 -> 0.0044742729 | Q36: =Q34/P34-1 -> -0.035634744 | R36: =R34/Q34-1 -> 0.073903002 | ... BA36: =BA34/AZ34-1 -> 0.033609452
A37: =ROWS($A$2:A37) -> 36 | B37: Depreciation as % of revenue | F37: 0.044576104 | G37: =(G34+G35)/G12 -> 0.046256104 | H37: =(H34+H35)/H12 -> 0.041110377 | I37: =(I34+I35)/I12 -> 0.038666329 | J37: 0.038351031 | K37: =(K34+K35)/K12 -> 0.03599679 | L37: =(L34+L35)/L12 -> 0.033409017 | M37: =(M34+M35)/M12 -> 0.03197768 | N37: =(N34+N35)/N12 -> 0.041783891 | O37: =(O34+O35)/O12 -> 0.04304285 | P37: =(P34+P35)/P12 -> 0.0418297 | Q37: =(Q34+Q35)/Q12 -> 0.039033625 | R37: =(R34+R35)/R12 -> 0.043992431 | ... AO37: =(AO34+AO35)/AO12 -> 0.040445803 | AP37: 0.055 | AQ37: 0.051 | AR37: 0.051 | AS37: 0.051 | AT37: 0.051 | AU37: 0.051 | AV37: 0.04 | AW37: 0.051 | AX37: 0.051 | AY37: 0.051 | AZ37: 0.04 | BA37: 0.04 | BN37: =BN34+BN35 -> 12863.239 | BO37: =BO34+BO35 -> 14465.156 | BP37: =BP34+BP35 -> 16051.129
A38: =ROWS($A$2:A38) -> 37 | BE38: 4.2588754 | BF38: =BF34/BF12*100 -> 3.3948099 | BG38: =BG34/BG12*100 -> 4.1348981 | BH38: =BH34/BH12*100 -> 3.9375483 | BI38: =BI34/BI12*100 -> 3.5323383 | BJ38: =BJ34/BJ12*100 -> 3.2253637 | BK38: =BK34/BK12*100 -> 3.2989599 | BL38: =BL34/BL12*100 -> 3.5416995 | BM38: =BM34/BM12*100 -> 4.1572424 | BN38: =BN37/BN12*100 -> 5.188676 | BO38: =BO37/BO12*100 -> 4.8209223 | BP38: =BP37/BP12*100 -> 4.5314545
A39: =ROWS($A$2:A39) -> 38 | B39: EBIT | F39: 792 | G39: =G29-G34-G35 -> 849 | H39: =H29-H34-H35 -> 985 | I39: =I29-I34-I35 -> 1113 | J39: 980 | K39: =K29-K34-K35 -> 1239 | L39: =L29-L34-L35 -> 1368 | M39: =M29-M34-M35 -> 1287 | N39: =N29-N34-N35 -> 1005 | O39: =O29-O34-O35 -> 1451 | P39: =P29-P34-P35 -> 1491 | Q39: =Q29-Q34-Q35 -> 1538 | R39: =R29-R34-R35 -> 1221 | ... BA39: =BA29-BA34-BA35 -> 13785.877 | BE39: 3738 | BF39: =BF29-BF34-BF35 -> 5204 | BG39: =BG29-BG34-BG35 -> 5467 | BH39: =BH29-BH34-BH35 -> 6028 | BI39: =BI29-BI34-BI35 -> 8882 | BJ39: =BJ29-BJ34-BJ35 -> 11468 | BK39: 12196 | BL39: =BL29-BL34-BL35 -> 12942 | BM39: =BM29-BM34-BM35 -> 23645 | BN39: =BN29-BN34-BN35 -> 38192.786 | BO39: =BO29-BO34-BO35 -> 46444.497 | BP39: =BP29-BP34-BP35 -> 53476.57
A40: =ROWS($A$2:A40) -> 39 | B40: % of revenue | F40: 0.11172239 | G40: =G39/G12 -> 0.11516549 | H40: =H39/H12 -> 0.13020489 | I40: =I39/I12 -> 0.14110041 | J40: 0.12242349 | K40: =K39/K12 -> 0.14203829 | L40: =L39/L12 -> 0.14790788 | M40: =M39/M12 -> 0.13810495 | N40: =N39/N12 -> 0.10472023 | O40: =O39/O12 -> 0.13972075 | P40: =P39/P12 -> 0.13890442 | Q40: =Q39/Q12 -> 0.13864599 | R40: =R39/R12 -> 0.11551561 | ... BA40: =BA39/BA12 -> 0.14815114 | BE40: 0.12495821 | BF40: =BF39/BF12 -> 0.14155922 | BG40: =BG39/BG12 -> 0.13066756 | BH40: =BH39/BH12 -> 0.12927855 | BI40: =BI39/BI12 -> 0.1380908 | BJ40: =BJ39/BJ12 -> 0.14308886 | BK40: =BK39/BK12 -> 0.13537724 | BL40: =BL39/BL12 -> 0.10719522 | BM40: =BM39/BM12 -> 0.1441531 | ... BP40: =BP39/BP12 -> 0.15097171
...

Sheet Revenue and Cost model
A2: Operating model (Rs. mn) | B2: Q1FY19 | C2: Q2FY19 | D2: Q3FY19 | E2: Q4FY19 | F2: Q1FY20 | G2: Q2FY20 | H2: Q3FY20 | I2: Q4FY20 | J2: Q1FY21 | K2: Q2FY21 | L2: Q3FY21 | M2: Q4FY21 | N2: Q1FY22 | O2: Q2FY22 | P2: Q3FY22 | Q2: Q4FY22 | R2: Q1FY23 | S2: Q2FY23 | T2: Q3FY23 | U2: Q4FY23 | V2: Q1FY24 | W2: Q2FY24 | X2: Q3FY24 | Y2: Q4FY24 | Z2: Q1FY25 | AA2: Q2FY25 | AB2: Q3FY25 | AC2: Q4FY25 | AD2: Q1FY26 | AE2: Q2FY26 | AF2: Q3FY26 | AG2: Q4FY26 | AH2: Q1FY27 | AI2: Q2FY27 | AJ2: Q3FY27 | AK2: Q4FY27 | AL2: Q1FY28 | AM2: Q2FY28 | AN2: Q3FY28 | AO2: Q4FY28 | AP2: Q1FY29 | AQ2: Q2FY29 | AR2: Q3FY29 | AS2: Q4FY29 | AV2: FY15 | AW2: FY16 | AX2: FY17 | AY2: FY18 | AZ2: FY19 | BA2: FY20 | BB2: FY21 | BC2: FY22 | BD2: FY23 | BE2: FY24 | BF2: FY25 | BG2: FY26 | BH2: FY27 | BI2: FY28 | BJ2: FY29 | BK2: FY30 Target
A3: INR/US$ | B3: 67.52 | C3: 70.51 | D3: 71.66 | E3: 69.28 | F3: 68.5 | G3: 70.66 | H3: 70.97 | I3: 71.66 | J3: 75.553967 | K3: 74.48031 | L3: 74.042289 | M3: 73.300407 | N3: 73.189785 | O3: 73.75 | P3: 74.824007 | Q3: 75.3 | R3: 76.640134 | S3: 79.360065 | T3: 81.676599 | U3: 82.072617 | V3: 81.714496 | W3: 81.848256 | X3: 82.386525 | Y3: 82.53471 | Z3: 82.300978 | AA3: 82.870446 | AB3: 83.434059 | AC3: 84.812887 | AD3: 83.377034 | AE3: 86.251894 | AF3: 87.991266 | AG3: 90.991617 | AH3: 93.5 | AI3: 93.5 | AJ3: 93.5 | AK3: 93.5 | AL3: 95.5 | AM3: 95.5 | AN3: 95.5 | AO3: 95.5 | AP3: 97 | AQ3: 97 | AR3: 97 | AS3: 97
A5: Revenue Model
A7: Headcount
A8: Onsite | B8: 2217 | C8: 2369 | D8: 2408 | E8: 2345 | F8: 2429 | G8: 2468 | H8: 2451 | I8: 2451 | J8: 2260 | K8: 2524 | L8: 2506 | M8: 2536 | N8: 3361 | O8: 3458 | P8: 3360 | Q8: 3407.04 | R8: 3638.72 | S8: 3678.56 | T8: 3600.8 | U8: 3483.6 | V8: 3633.6 | W8: 3695.7 | X8: 3691.05 | Y8: 3708.9 | Z8: 3916.65 | AA8: 4207.95 | AB8: 4964.1 | AC8: 4953.45 | AD8: 5128.05 | AE8: 5234.4 | AF8: 5301.15 | AG8: 5366.55 | AH8: 7184.0216 | AI8: 7191.2056 | AJ8: 7184.0144 | AK8: 7219.9345 | AL8: 7256.0342 | AM8: 7328.5945 | AN8: 7321.2659 | AO8: 7357.8722 | AP8: 7394.6616 | AQ8: 7468.6082 | AR8: 7461.1396 | AS8: 7498.4453 | AZ8: 2345 | BA8: 2451 | BB8: 2536 | BC8: 3407.04
A9: Offshore | B9: 6684 | C9: 2369 | D9: 6881 | E9: 7018 | F9: 7063 | G9: 7453 | H9: 7515 | I9: 7823 | J9: 7476 | K9: 7757 | L9: 8032 | M9: 8933 | N9: 15978 | O9: 16121 | P9: 17578 | Q9: 17886.96 | R9: 17855.28 | S9: 18013.44 | T9: 17552.2 | U9: 18331.4 | V9: 19128.4 | W9: 19435.3 | X9: 19415.95 | Y9: 19534.1 | Z9: 20647.35 | AA9: 22252.05 | AB9: 26016.9 | AC9: 25934.55 | AD9: 26884.95 | AE9: 27475.6 | AF9: 27876.85 | AG9: 28276.45 | AH9: 35037.943 | AI9: 35072.981 | AJ9: 35037.908 | AK9: 35213.098 | AL9: 35389.163 | AM9: 35743.055 | AN9: 35707.312 | AO9: 35885.849 | AP9: 36065.278 | AQ9: 36425.931 | AR9: 36389.505 | AS9: 36571.452 | AZ9: 7018 | BA9: 7823 | BB9: 8933 | BC9: 17886.96
A10: Billable | B10: 8901 | C10: 4738 | D10: 9289 | E10: 9363 | F10: 9492 | G10: 9921 | H10: 9966 | I10: 10274 | J10: 9736 | K10: 10281 | L10: 10538 | M10: 11469 | N10: 19339 | O10: 19579 | P10: 20938 | Q10: 21294 | R10: 21494 | S10: 21692 | T10: 21153 | U10: 21815 | V10: 22762 | W10: 23131 | X10: 23107 | Y10: 23243 | Z10: 24564 | AA10: 26460 | AB10: 30981 | AC10: 30888 | AD10: 32013 | AE10: 32710 | AF10: 33178 | AG10: 33643 | AH10: 42221.965 | AI10: 42264.187 | AJ10: 42221.923 | AK10: 42433.032 | AL10: 42645.198 | AM10: 43071.65 | AN10: 43028.578 | AO10: 43243.721 | AP10: 43459.939 | AQ10: 43894.539 | AR10: 43850.644 | AS10: 44069.897 | AZ10: 9363 | BA10: 10274 | BB10: 11469 | BC10: 21294
A11: Sales and Development | B11: 221 | C11: 217 | D11: 208 | E11: 211 | F11: 141 | G11: 185 | H11: 185 | I11: 170 | J11: 184 | K11: 191 | L11: 189 | M11: 188 | N11: 258 | O11: 297 | P11: 281 | Q11: 278 | R11: 285 | S11: 291 | T11: 317 | U11: 350 | V11: 363 | W11: 360 | X11: 368 | Y11: 388 | Z11: 424 | AA11: 443 | AB11: 583 | AC11: 569 | AD11: 594 | AE11: 622 | AF11: 617 | AG11: 577 | AH11: 2678.17 | AI11: 2680.8482 | AJ11: 2678.1673 | AK11: 2691.5582 | AL11: 2705.0159 | AM11: 2732.0661 | AN11: 2729.334 | AO11: 2742.9807 | AP11: 2756.6956 | AQ11: 2784.2626 | AR11: 2781.4783 | AS11: 2795.3857 | AZ11: 211 | BA11: 170 | BB11: 188 | BC11: 278
A12: Others | E12: 689 | F12: 664 | G12: 694 | H12: 698 | I12: 712 | J12: 678 | K12: 690 | L12: 697 | M12: 734 | N12: 894 | O12: 910 | P12: 911 | Q12: 928 | R12: 963 | S12: 1008 | T12: 1035 | U12: 1059 | V12: 1099 | W12: 1147 | X12: 1132 | Y12: 1095 | Z12: 1123 | AA12: 1150 | AB12: 1530 | AC12: 1566 | AD12: 1580 | AE12: 1564 | AF12: 1546 | AG12: 1557 | AZ12: 689 | BA12: 712 | BB12: 734 | BC12: 928
A13: Total | B13: 9122 | C13: 4955 | D13: 9497 | E13: 10263 | F13: 10297 | G13: 10800 | H13: 10849 | I13: 11156 | J13: 10598 | K13: 11162 | L13: 11424 | M13: 12391 | N13: 20491 | O13: 20786 | P13: 22130 | Q13: 22500 | R13: 22742 | S13: 22991 | T13: 22505 | U13: 23224 | V13: 24224 | W13: 24638 | X13: 24607 | Y13: 24726 | Z13: 26111 | AA13: 28053 | AB13: 33094 | AC13: 33023 | AD13: 34187 | AE13: 34896 | AF13: 35341 | AG13: 35777 | AH13: 44900.135 | AI13: 44945.035 | AJ13: 44900.09 | AK13: 45124.591 | AL13: 45350.214 | AM13: 45803.716 | AN13: 45757.912 | AO13: 45986.701 | AP13: 46216.635 | AQ13: 46678.801 | AR13: 46632.123 | AS13: 46865.283 | AX13: 0 | AY13: 0 | AZ13: 10263 | BA13: 11156 | BB13: 12391 | BC13: 22500
A15: Gross addition | B15: 9122 | C15: -4167 | D15: 4542 | E15: 1056.6082 | F15: 367.03435 | G15: 819.63275 | H15: 370.3 | I15: 627.0455 | J15: -228.898 | K15: 842.1975 | L15: 552.212 | M15: 1266.88 | N15: 8490.3165 | O15: 1078.7807 | P15: 2191.0295 | Q15: 1349.2525 | R15: 1254.5 | S15: 1181.422 | T15: 422.1445 | U15: 1512.3012 | V15: 1772.198 | W15: 1201.28 | X15: 714.2995 | Y15: 826.45125 | Z15: 2089.691 | AA15: 2686.1635 | AB15: 5875.5768 | AC15: 830.8115 | AD15: 2096.8998 | AE15: 1683.3295 | AF15: 1395.916 | AG15: 1390.207 | AZ15: 1056.6082 | BA15: 627.0455 | BB15: 1266.88 | BC15: 1349.2525
A16: Attrition | B16: 0 | C16: 0 | D16: 0 | E16: 290.6082 | F16: 333.03435 | G16: 316.63275 | H16: 321.3 | I16: 320.0455 | J16: 329.102 | K16: 278.1975 | L16: 290.212 | M16: 299.88 | N16: 390.3165 | O16: 783.78075 | P16: 847.0295 | Q16: 979.2525 | R16: 1012.5 | S16: 932.422 | T16: 908.1445 | U16: 793.30125 | V16: 772.198 | W16: 787.28 | X16: 745.2995 | Y16: 707.45125 | Z16: 704.691 | AA16: 744.1635 | AB16: 834.57675 | AC16: 901.8115 | AD16: 932.89975 | AE16: 974.3295 | AF16: 950.916 | AG16: 954.207 | AZ16: 290.6082 | BA16: 320.0455 | BB16: 299.88 | BC16: 979.2525
A17: Attrition % | B17: 0 | C17: 0 | D17: 0 | E17: 12.24 | F17: 12.98 | G17: 12.3 | H17: 11.9 | I17: 11.8 | J17: 11.8 | K17: 10.5 | L17: 10.4 | M17: 10.5 | N17: 12.6 | O17: 15.3 | P17: 16.3 | Q17: 17.7 | R17: 18 | S17: 16.4 | T17: 15.8 | U17: 14.1 | V17: 13.3 | W17: 13 | X17: 12.1 | Y17: 11.5 | Z17: 11.4 | AA17: 11.4 | AB17: 11.9 | AC17: 10.9 | AD17: 11.3 | AE17: 11.4 | AF17: 10.9 | AG17: 10.8 | AZ17: 12.24 | BA17: 11.8 | BB17: 10.5 | BC17: 17.7
A18: Net addition | B18: 9122 | C18: -4167 | D18: 4542 | E18: 766 | F18: 34 | G18: 503 | H18: 49 | I18: 307 | J18: -558 | K18: 564 | L18: 262 | M18: 967 | N18: 8100 | O18: 295 | P18: 1344 | Q18: 370 | R18: 242 | S18: 249 | T18: -486 | U18: 719 | V18: 1000 | W18: 414 | X18: -31 | Y18: 119 | Z18: 1385 | AA18: 1942 | AB18: 5041 | AC18: -71 | AD18: 1164 | AE18: 709 | AF18: 445 | AG18: 436 | AH18: 9123.135 | AI18: 44.900135 | AJ18: -44.945035 | AK18: 224.50045 | AL18: 225.62295 | AM18: 453.50214 | AN18: -45.803716 | AO18: 228.78956 | AP18: 229.93351 | AQ18: 462.16635 | AR18: -46.678801 | AS18: 233.16061 | AZ18: 766 | BA18: 307 | BB18: 967 | BC18: 370
A20: Headcount (as % of total)
A21: Total Billable | B21: 0.97577286 | C21: 0.95620585 | D21: 0.97809835 | E21: 0.91230634 | F21: 0.92182189 | G21: 0.91861111 | H21: 0.91861001 | I21: 0.9209394 | J21: 0.9186639 | K21: 0.92107149 | L21: 0.92244398 | M21: 0.92559115 | N21: 0.9437802 | O21: 0.94193207 | P21: 0.94613647 | Q21: 0.9464 | R21: 0.94512356 | S21: 0.94349963 | T21: 0.93992446 | U21: 0.93933 | V21: 0.93964663 | W21: 0.93883432 | X21: 0.93904174 | Y21: 0.94002265 | Z21: 0.94075294 | AA21: 0.94321463 | AB21: 0.93615157 | AC21: 0.93534809 | AD21: 0.93640858 | AE21: 0.93735672 | AF21: 0.9387963 | AG21: 0.94035274 | AH21: 0.94035274 | AI21: 0.94035274 | AJ21: 0.94035274 | AK21: 0.94035274 | AL21: 0.94035274 | AM21: 0.94035274 | AN21: 0.94035274 | AO21: 0.94035274 | AP21: 0.94035274 | AQ21: 0.94035274 | AR21: 0.94035274 | AS21: 0.94035274
A22: Onsite | B22: 0.24303881 | C22: 0.47810293 | D22: 0.25355375 | E22: 0.22849069 | F22: 0.23589395 | G22: 0.22851852 | H22: 0.22591944 | I22: 0.2197024 | J22: 0.21324778 | K22: 0.22612435 | L22: 0.21936275 | M22: 0.20466468 | N22: 0.16402323 | O22: 0.16636197 | P22: 0.15183009 | Q22: 0.16 | R22: 0.16 | S22: 0.16 | T22: 0.16 | U22: 0.15 | V22: 0.15 | W22: 0.15 | X22: 0.15 | Y22: 0.15 | Z22: 0.15 | AA22: 0.15 | AB22: 0.15 | AC22: 0.15 | AD22: 0.15 | AE22: 0.15 | AF22: 0.15 | AG22: 0.15 | AH22: 0.16 | AI22: 0.16 | AJ22: 0.16 | AK22: 0.16 | AL22: 0.16 | AM22: 0.16 | AN22: 0.16 | AO22: 0.16 | AP22: 0.16 | AQ22: 0.16 | AR22: 0.16 | AS22: 0.16
A23: Offshore | B23: 0.73273405 | C23: 0.47810293 | D23: 0.72454459 | E23: 0.68381565 | F23: 0.68592794 | G23: 0.69009259 | H23: 0.69269057 | I23: 0.701237 | J23: 0.70541612 | K23: 0.69494714 | L23: 0.70308123 | M23: 0.72092648 | N23: 0.77975697 | O23: 0.7755701 | P23: 0.79430637 | Q23: 0.7864 | R23: 0.78512356 | S23: 0.78349963 | T23: 0.77992446 | U23: 0.78933 | V23: 0.78964663 | W23: 0.78883432 | X23: 0.78904174 | Y23: 0.79002265 | Z23: 0.79075294 | AA23: 0.79321463 | AB23: 0.78615157 | AC23: 0.78534809 | AD23: 0.78640858 | AE23: 0.78735672 | AF23: 0.7887963 | AG23: 0.79035274 | AH23: 0.78035274 | AI23: 0.78035274 | AJ23: 0.78035274 | AK23: 0.78035274 | AL23: 0.78035274 | AM23: 0.78035274 | AN23: 0.78035274 | AO23: 0.78035274 | AP23: 0.78035274 | AQ23: 0.78035274 | AR23: 0.78035274 | AS23: 0.78035274
A24: Sales and Development | B24: 0.024227143 | C24: 0.043794147 | D24: 0.021901653 | E24: 0.087693657 | F24: 0.07817811 | G24: 0.081388889 | H24: 0.08138999 | I24: 0.079060595 | J24: 0.081336101 | K24: 0.078928507 | L24: 0.077556022 | M24: 0.074408845 | N24: 0.056219804 | O24: 0.05806793 | P24: 0.053863534 | Q24: 0.0536 | R24: 0.05487644 | S24: 0.05650037 | T24: 0.060075539 | U24: 0.060669997 | V24: 0.060353369 | W24: 0.061165679 | X24: 0.060958264 | Y24: 0.059977352 | Z24: 0.059247061 | AA24: 0.056785371 | AB24: 0.063848432 | AC24: 0.064651909 | AD24: 0.063591424 | AE24: 0.062643283 | AF24: 0.061203701 | AG24: 0.059647259 | AH24: 0.059647259 | AI24: 0.059647259 | AJ24: 0.059647259 | AK24: 0.059647259 | AL24: 0.059647259 | AM24: 0.059647259 | AN24: 0.059647259 | AO24: 0.059647259 | AP24: 0.059647259 | AQ24: 0.059647259 | AR24: 0.059647259 | AS24: 0.059647259
A25: - Total headcount growth (qoq) | E25: 0.08065705 | F25: 0.0033128715 | G25: 0.048849179 | H25: 0.004537037 | I25: 0.028297539 | J25: -0.050017928 | K25: 0.053217588 | L25: 0.023472496 | M25: 0.084646359 | N25: 0.65370027 | O25: 0.014396564 | P25: 0.064658905 | Q25: 0.016719385 | R25: 0.010755556 | S25: 0.010948905 | T25: -0.021138706 | U25: 0.031948456 | V25: 0.043058905 | W25: 0.017090489 | X25: -0.001258219 | Y25: 0.0048360223 | Z25: 0.056013912 | AA25: 0.074374785 | AB25: 0.17969558 | AC25: -0.002145404 | AD25: 0.03524816 | AE25: 0.020738877 | AF25: 0.012752178 | AG25: 0.012336946 | AH25: 0.255 | AI25: 0.001 | AJ25: -0.001 | AK25: 0.005 | AL25: 0.005 | AM25: 0.01 | AN25: -0.001 | AO25: 0.005 | AP25: 0.005 | AQ25: 0.01 | AR25: -0.001 | AS25: 0.005
A27: Utilizaiton
A29: Utilization (incl trainees) - reported | B29: 0 | C29: 0 | D29: 0 | E29: 79.3 | F29: 80.5 | G29: 80.7 | H29: 79.3 | I29: 78.1 | J29: 77 | K29: 81 | L29: 78.9 | M29: 81 | N29: 77 | O29: 78.5 | P29: 77.1 | Q29: 76.1 | R29: 76.2 | S29: 77.3 | T29: 80.3 | U29: 81.5 | V29: 81 | W29: 80 | X29: 79.4 | Y29: 81.7 | Z29: 81.4 | AA29: 81.7 | AB29: 81.3 | AC29: 82 | AD29: 82.1 | AE29: 82.3 | AF29: 81.7 | AG29: 82.5
A30: Utilization (excl trainees) - reported
A32: Utilization (Calculated)
A33: Onsite utilization | B33: 0.9 | C33: 0.9 | D33: 0.9 | E33: 0.9 | F33: 0.9 | G33: 0.9 | H33: 0.9 | I33: 0.9 | J33: 0.9 | K33: 0.9 | L33: 0.9 | M33: 0.9 | N33: 0.9 | O33: 0.9 | P33: 0.9 | Q33: 0.9 | R33: 0.9 | S33: 0.9 | T33: 0.9 | U33: 0.91 | V33: 0.91 | W33: 0.91 | X33: 0.9 | Y33: 0.9 | Z33: 0.91 | AA33: 0.91 | AB33: 0.91 | AC33: 0.91 | AD33: 0.91 | AE33: 0.91 | AF33: 0.91 | AG33: 0.91 | AH33: 0.9 | AI33: 0.9 | AJ33: 0.9 | AK33: 0.9 | AL33: 0.9 | AM33: 0.9 | AN33: 0.9 | AO33: 0.9 | AP33: 0.9 | AQ33: 0.9 | AR33: 0.9 | AS33: 0.9
A34: Offshore utilization | B34: -0.29851885 | C34: -0.9 | D34: -0.31495422 | E34: 0.75724694 | F34: 0.77232904 | G34: 0.77620381 | H34: 0.7581022 | I34: 0.74371648 | J34: 0.73070091 | K34: 0.78071548 | L34: 0.75436778 | M34: 0.78444979 | N34: 0.74265427 | O34: 0.76033218 | P34: 0.7463419 | Q34: 0.73452381 | R34: 0.73387704 | S34: 0.74706508 | T34: 0.78310064 | U34: 0.79694671 | V34: 0.79100416 | W34: 0.77908306 | X34: 0.77384897 | Y34: 0.80124096 | Z34: 0.79578951 | AA34: 0.79941333 | AB34: 0.79449212 | AC34: 0.80281017 | AD34: 0.80402409 | AE34: 0.80642556 | AF34: 0.79931483 | AG34: 0.80886796 | AH34: 0.81 | AI34: 0.81 | AJ34: 0.81 | AK34: 0.81 | AL34: 0.81 | AM34: 0.81 | AN34: 0.81 | AO34: 0.81 | AP34: 0.81 | AQ34: 0.81 | AR34: 0.81 | AS34: 0.81
A35: Blended utilization | B35: 0 | C35: 0 | D35: 0 | E35: 0.793 | F35: 0.805 | G35: 0.807 | H35: 0.793 | I35: 0.781 | J35: 0.77 | K35: 0.81 | L35: 0.789 | M35: 0.81 | N35: 0.77 | O35: 0.785 | P35: 0.771 | Q35: 0.761 | R35: 0.762 | S35: 0.773 | T35: 0.803 | U35: 0.815 | V35: 0.81 | W35: 0.8 | X35: 0.794 | Y35: 0.817 | Z35: 0.814 | AA35: 0.817 | AB35: 0.813 | AC35: 0.82 | AD35: 0.821 | AE35: 0.823 | AF35: 0.817 | AG35: 0.825 | AH35: 0.8253134 | AI35: 0.8253134 | AJ35: 0.8253134 | AK35: 0.8253134 | AL35: 0.8253134 | AM35: 0.8253134 | AN35: 0.8253134 | AO35: 0.8253134 | AP35: 0.8253134 | AQ35: 0.8253134 | AR35: 0.8253134 | AS35: 0.8253134
A37: Billable Person Months | B37: 26703 | C37: 14214 | D37: 27867 | E37: 28089 | F37: 28476 | G37: 29763 | H37: 29898 | I37: 30822 | J37: 29208 | K37: 30843 | L37: 31614 | M37: 34407 | N37: 58017 | O37: 58737 | P37: 62814 | Q37: 63882 | R37: 64482 | S37: 65076 | T37: 63459 | U37: 65445 | V37: 68286 | W37: 69393 | X37: 69321 | Y37: 69729 | Z37: 73692 | AA37: 79380 | AB37: 92943 | AC37: 92664 | AD37: 96039 | AE37: 98130 | AF37: 99534 | AG37: 100929 | AH37: 126665.89 | AI37: 126792.56 | AJ37: 126665.77 | AK37: 127299.1 | AL37: 127935.59 | AM37: 129214.95 | AN37: 129085.73 | AO37: 129731.16 | AP37: 130379.82 | AQ37: 131683.62 | AR37: 131551.93 | AS37: 132209.69
A38: - Onsite | B38: 6651 | C38: 7107 | D38: 7224 | E38: 7035 | F38: 7287 | G38: 7404 | H38: 7353 | I38: 7353 | J38: 6780 | K38: 7572 | L38: 7518 | M38: 7608 | N38: 10083 | O38: 10374 | P38: 10080 | Q38: 10221.12 | R38: 10916.16 | S38: 11035.68 | T38: 10802.4 | U38: 10450.8 | V38: 10900.8 | W38: 11087.1 | X38: 11073.15 | Y38: 11126.7 | Z38: 11749.95 | AA38: 12623.85 | AB38: 14892.3 | AC38: 14860.35 | AD38: 15384.15 | AE38: 15703.2 | AF38: 15903.45 | AG38: 16099.65 | AH38: 21552.065 | AI38: 21573.617 | AJ38: 21552.043 | AK38: 21659.803 | AL38: 21768.102 | AM38: 21985.784 | AN38: 21963.798 | AO38: 22073.617 | AP38: 22183.985 | AQ38: 22405.825 | AR38: 22383.419 | AS38: 22495.336
A39: - Offshore | B39: 20052 | C39: 7107 | D39: 20643 | E39: 21054 | F39: 21189 | G39: 22359 | H39: 22545 | I39: 23469 | J39: 22428 | K39: 23271 | L39: 24096 | M39: 26799 | N39: 47934 | O39: 48363 | P39: 52734 | Q39: 53660.88 | R39: 53565.84 | S39: 54040.32 | T39: 52656.6 | U39: 54994.2 | V39: 57385.2 | W39: 58305.9 | X39: 58247.85 | Y39: 58602.3 | Z39: 61942.05 | AA39: 66756.15 | AB39: 78050.7 | AC39: 77803.65 | AD39: 80654.85 | AE39: 82426.8 | AF39: 83630.55 | AG39: 84829.35 | AH39: 105113.83 | AI39: 105218.94 | AJ39: 105113.73 | AK39: 105639.29 | AL39: 106167.49 | AM39: 107229.17 | AN39: 107121.94 | AO39: 107657.55 | AP39: 108195.83 | AQ39: 109277.79 | AR39: 109168.51 | AS39: 109714.36
A41: Billed Person Months | B41: 0 | C41: 0 | D41: 0 | E41: 22274.577 | F41: 22923.18 | G41: 24018.741 | H41: 23709.114 | I41: 24071.982 | J41: 22490.16 | K41: 24982.83 | L41: 24943.446 | M41: 27869.67 | N41: 44673.09 | O41: 46108.545 | P41: 48429.594 | Q41: 48614.202 | R41: 49135.284 | S41: 50303.748 | T41: 50957.577 | U41: 53337.675 | V41: 55311.66 | W41: 55514.4 | X41: 55040.874 | Y41: 56968.593 | Z41: 59985.288 | AA41: 64853.46 | AB41: 75562.659 | AC41: 75984.48 | AD41: 78848.019 | AE41: 80760.99 | AF41: 81319.278 | AG41: 83266.425 | AH41: 104539.06 | AI41: 104643.6 | AJ41: 104538.96 | AK41: 105061.65 | AL41: 105586.96 | AM41: 106642.83 | AN41: 106536.19 | AO41: 107068.87 | AP41: 107604.21 | AQ41: 108680.25 | AR41: 108571.57 | AS41: 109114.43
A42: - Onsite | B42: 5985.9 | C42: 6396.3 | D42: 6501.6 | E42: 6331.5 | F42: 6558.3 | G42: 6663.6 | H42: 6617.7 | I42: 6617.7 | J42: 6102 | K42: 6814.8 | L42: 6766.2 | M42: 6847.2 | N42: 9074.7 | O42: 9336.6 | P42: 9072 | Q42: 9199.008 | R42: 9824.544 | S42: 9932.112 | T42: 9722.16 | U42: 9510.228 | V42: 9919.728 | W42: 10089.261 | X42: 9965.835 | Y42: 10014.03 | Z42: 10692.454 | AA42: 11487.703 | AB42: 13551.993 | AC42: 13522.918 | AD42: 13999.577 | AE42: 14289.912 | AF42: 14472.139 | AG42: 14650.682 | AH42: 19396.858 | AI42: 19416.255 | AJ42: 19396.839 | AK42: 19493.823 | AL42: 19591.292 | AM42: 19787.205 | AN42: 19767.418 | AO42: 19866.255 | AP42: 19965.586 | AQ42: 20165.242 | AR42: 20145.077 | AS42: 20245.802 | BA42: 26457.3 | BB42: 26530.2 | BC42: 36682.308
A43: - Offshore | B43: -5985.9 | C43: -6396.3 | D43: -6501.6 | E43: 15943.077 | F43: 16364.88 | G43: 17355.141 | H43: 17091.414 | I43: 17454.282 | J43: 16388.16 | K43: 18168.03 | L43: 18177.246 | M43: 21022.47 | N43: 35598.39 | O43: 36771.945 | P43: 39357.594 | Q43: 39415.194 | R43: 39310.74 | S43: 40371.636 | T43: 41235.417 | U43: 43827.447 | V43: 45391.932 | W43: 45425.139 | X43: 45075.039 | Y43: 46954.563 | Z43: 49292.834 | AA43: 53365.757 | AB43: 62010.666 | AC43: 62461.561 | AD43: 64848.442 | AE43: 66471.078 | AF43: 66847.139 | AG43: 68615.743 | AH43: 85142.202 | AI43: 85227.345 | AJ43: 85142.117 | AK43: 85567.828 | AL43: 85995.667 | AM43: 86855.624 | AN43: 86768.768 | AO43: 87202.612 | AP43: 87638.625 | AQ43: 88515.011 | AR43: 88426.496 | AS43: 88868.629 | BA43: 68265.717 | BB43: 73755.906 | BC43: 151143.12
A45: Billing rates - USD/ppm - Onsite | B45: 0 | C45: 0 | D45: 0 | E45: 14021.638 | F45: 14099.301 | G45: 14556.866 | H45: 14627.149 | I45: 14970.803 | J45: 14145.903 | K45: 14547.162 | L45: 14734.415 | M45: 15281.692 | N45: 13203.742 | O45: 12763.533 | P45: 13190.476 | Q45: 13389.705 | R45: 12634.072 | S45: 12479.098 | T45: 12815.208 | U45: 13706.212 | V45: 13425.973 | W45: 13230.701 | X45: 13525.811 | Y45: 13324.056 | Z45: 12749.776 | AA45: 14683.196 | AB45: 13514.212 | AC45: 13755.426 | AD45: 15073.656 | AE45: 15424.987 | AF45: 15684.26 | AG45: 15890.838 | AH45: 16129.2 | AI45: 16322.751 | AJ45: 16485.978 | AK45: 16683.81 | AL45: 16934.067 | AM45: 17137.276 | AN45: 17308.648 | AO45: 17516.352 | AP45: 17779.098 | AQ45: 17992.447 | AR45: 18172.371 | AS45: 18390.44 | BA45: 14564.561 | BB45: 14692.204 | BC45: 13135.051
A46: - growth % | B46: #DIV/0! | C46: #DIV/0! | D46: #DIV/0! | E46: #DIV/0! | F46: 0.0055387763 | G46: 0.032453032 | H46: 0.0048281669 | I46: 0.023494288 | J46: -0.055100612 | K46: 0.028365745 | L46: 0.012872141 | M46: 0.037142744 | N46: -0.13597641 | O46: -0.033339753 | P46: 0.033450255 | Q46: 0.015103961 | R46: -0.056433825 | S46: -0.012266376 | T46: 0.026933808 | U46: 0.069527094 | V46: -0.020446124 | W46: -0.014544312 | X46: 0.022304902 | Y46: -0.014916265 | Z46: -0.043101013 | AA46: 0.15164343 | AB46: -0.079613751 | AC46: 0.017848923 | AD46: 0.095833481 | AE46: 0.023307587 | AF46: 0.016808674 | AG46: 0.013171006 | AH46: 0.015 | AI46: 0.012 | AJ46: 0.01 | AK46: 0.012 | AL46: 0.015 | AM46: 0.012 | AN46: 0.01 | AO46: 0.012 | AP46: 0.015 | AQ46: 0.012 | AR46: 0.01 | AS46: 0.012
A47: Billing rates - USD/ppm - Offshore | B47: 0 | C47: 0 | D47: 0 | E47: 2868.5882 | F47: 2910.7909 | G47: 2879.2783 | H47: 3185.7471 | I47: 3192.8074 | J47: 3269.5373 | K47: 3069.3476 | L47: 3361.5653 | M47: 3209.0996 | N47: 2243.9217 | O47: 2546.289 | P47: 2589.9957 | Q47: 2771.2156 | R47: 2914.6233 | S47: 3045.6086 | T47: 3082.5079 | U47: 3058.6039 | V47: 3053.8026 | W47: 3183.5236 | X47: 3265.7542 | Y47: 3140.7491 | Z47: 3044.5318 | AA47: 3680.7086 | AB47: 3343.8683 | AC47: 3481.9254 | AD47: 3567.9377 | AE47: 3635.8414 | AF47: 3798.4453 | AG47: 3735.1253 | AH47: 3753.8009 | AI47: 3772.5699 | AJ47: 3791.4328 | AK47: 3810.39 | AL47: 3829.4419 | AM47: 3848.5891 | AN47: 3867.8321 | AO47: 3887.1712 | AP47: 3906.6071 | AQ47: 3926.1401 | AR47: 3945.7708 | AS47: 3965.4997 | BA47: 3043.7256 | BB47: 3225.6793 | BC47: 2545.1108
A48: - growth % | B48: #DIV/0! | C48: #DIV/0! | D48: #DIV/0! | E48: #DIV/0! | F48: 0.01471203 | G48: -0.010826158 | H48: 0.10643945 | I48: 0.0022162246 | J48: 0.024032102 | K48: -0.061228736 | L48: 0.095205147 | M48: -0.045355577 | N48: -0.30076283 | O48: 0.1347495 | P48: 0.01716486 | Q48: 0.069969177 | R48: 0.051749039 | S48: 0.044940704 | T48: 0.012115601 | U48: -0.0077547375 | V48: -0.0015697658 | W48: 0.0424785 | X48: 0.025830087 | Y48: -0.038277582 | Z48: -0.030635128 | AA48: 0.20895719 | AB48: -0.091515075 | AC48: 0.041286657 | AD48: 0.024702487 | AE48: 0.019031662 | AF48: 0.044722488 | AG48: -0.01666998 | AH48: 0.005 | AI48: 0.005 | AJ48: 0.005 | AK48: 0.005 | AL48: 0.005 | AM48: 0.005 | AN48: 0.005 | AO48: 0.005 | AP48: 0.005 | AQ48: 0.005 | AR48: 0.005 | AS48: 0.005
A50: Reported onsite revenues (US$m) | B50: 0 | C50: 0 | D50: 0 | E50: 88.778002 | F50: 92.467445 | G50: 97.001132 | H50: 96.798084 | I50: 99.072286 | J50: 86.3183 | K50: 99.136 | L50: 99.696 | M50: 104.6368 | N50: 119.82 | O50: 119.168 | P50: 119.664 | Q50: 123.172 | R50: 124.124 | S50: 123.9438 | T50: 124.5915 | U50: 130.3492 | V50: 133.182 | W50: 133.488 | X50: 134.796 | Y50: 133.4275 | Z50: 136.3264 | AA50: 168.6762 | AB50: 183.1445 | AC50: 186.0135 | AD50: 211.0248 | AE50: 220.4217 | AF50: 226.9848 | AG50: 232.8116 | BA50: 385.33895 | BB50: 389.7871 | BC50: 481.824
A51: Reported offshore revenues (US$m) | B51: 0 | C51: 0 | D51: 0 | E51: 45.734122 | F51: 47.634745 | G51: 49.97028 | H51: 54.448922 | I51: 55.728161 | J51: 53.5817 | K51: 55.764 | L51: 61.104 | M51: 67.4632 | N51: 79.88 | O51: 93.632 | P51: 101.936 | Q51: 109.228 | R51: 114.576 | S51: 122.9562 | T51: 127.1085 | U51: 134.0508 | V51: 138.618 | W51: 144.612 | X51: 147.204 | Y51: 147.4725 | Z51: 150.0736 | AA51: 196.4238 | AB51: 207.3555 | AC51: 217.4865 | AD51: 231.3752 | AE51: 241.6783 | AF51: 253.9152 | AG51: 256.2884 | BA51: 207.78211 | BB51: 237.9129 | BC51: 384.676
A53: Billing rates - USD/per hour - Onsite | E53: 79.668399 | F53: 80.109664 | G53: 82.709466 | H53: 83.108801 | I53: 85.061383 | J53: 80.374449 | K53: 82.65433 | L53: 83.718268 | M53: 86.827794 | N53: 75.021263 | O53: 72.520073 | P53: 74.945887 | Q53: 76.077867 | R53: 71.784502 | S53: 70.903966 | T53: 72.81368 | U53: 77.876204 | V53: 76.283937 | W53: 75.17444 | X53: 76.851198 | Y53: 75.704866 | Z53: 72.441909 | AA53: 83.427249 | AB53: 76.785293 | AC53: 78.155828 | AD53: 85.645773 | AE53: 87.641969 | AF53: 89.115114 | AG53: 90.28885
...

Sheet Sheet1
A1: FY26 | B1: FY30
A2: 625 | B2: 1000 | C2: =((B2/A2)^(1/4))-1 -> 0.12468265
A3: 321 | B3: 550 | C3: =((B3/A3)^(1/4))-1 -> 0.14410113
A4: 511 | B4: 850 | C4: =((B4/A4)^(1/4))-1 -> 0.13566308
